Workbook

Sheet Industry
A1: Timestamp | B1: Email | C1: Last Name | D1: First Name | E1: Industry | F1: Accommodation and Food Services | G1: Food and Beverage Services Group | H1: Cafes, Restaurants and Takeaway Food Services | I1: Administrative and Support Services | J1: Administrative Services Group | K1: Employment Services | L1: Other Administrative Services | M1: Building Cleaning, Pest Control and Other Support Services Group | N1: Building Cleaning, Pest Control and Gardening Services | O1: Agriculture, Forestry and Fishing | P1: Agriculture Group | Q1: Fruit and Tree Nut Growing | R1: Mushroom and Vegetable Growing | S1: Nursery and Floriculture Production | T1: Poultry Farming | U1: Sheep, Beef Cattle and Grain Farming | V1: Other Crop Growing | W1: Other Livestock Farming | X1: Agriculture, Forestry and Fishing Support Services Group | Y1: Agriculture and Fishing Support Services | Z1: Aquaculture | AA1: Fishing, Hunting and Trapping Group | AB1: Fishing | AC1: Forestry and Logging | AD1: Arts and Recreation Services | AE1: Creative and Performing Arts Activities | AF1: Gambling Activities | AG1: Heritage Activities | AH1: Parks and Gardens Operations | AI1: Sports and Recreation Activities | AJ1: Amusement and Other Recreation Activities | AK1: Horse and Dog Racing Activities | AL1: Sports and Physical Recreation Activities | AM1: Construction | AN1: Building Construction | AO1: Residential Building Construction | AP1: Construction Services | AQ1: Building Completion Services | AR1: Building Installation Services | AS1: Building Structure Services | AT1: Land Development and Site Preparation Services | AU1: Other Construction Services | AV1: Heavy and Civil Engineering Construction | AW1: Education and Training | AX1: Adult, Community and Other Education | AY1: Adult, Community and Other Education | AZ1: Preschool and School Education | BA1: School Education | BB1: Tertiary Education | BC1: Electricity Supply | BD1: Electricity Distribution | BE1: Electricity Generation | BF1: Waste Collection, Treatment and Disposal Services | BG1: Waste Collection Services | BH1: Waste Treatment, Disposal and Remediation Services | BI1: Water Supply, Sewerage and Drainage Services | BJ1: Financial and Insurance Services | BK1: Auxiliary Finance and Insurance Services | BL1: Auxiliary Finance and Investment Services | BM1: Finance | BN1: Depository Financial Intermediation | BO1: Insurance and Superannuation Funds | BP1: Health and General Insurance | BQ1: Health Care and Social Assistance | BR1: Hospitals | BS1: Medical and Other Health Care Services | BT1: Allied Health Services | BU1: Medical Services | BV1: Other Health Care Services | BW1: Residential Care Services | BX1: Social Assistance Services | BY1: Information Media and Telecommunications | BZ1: Broadcasting (except Internet) | CA1: Television Broadcasting | CB1: Internet Service Providers, Web Search Portals and Data Processing Services | CC1: Data Processing, Web Hosting and Electronic Information Storage Services | CD1: Library and Other Information Services | CE1: Motion Picture and Sound Recording Activities | CF1: Motion Picture and Video Activities | CG1: Sound Recording and Music Publishing | CH1: Publishing (except Internet and Music Publishing) | CI1: Newspaper, Periodical, Book and Directory Publishing | CJ1: Manufacturing | CK1: Basic Chemical and Chemical Product Manufacturing | CL1: Basic Chemical Manufacturing | CM1: Basic Polymer Manufacturing | CN1: Cleaning Compound and Toiletry Preparation Manufacturing | CO1: Fertiliser and Pesticide Manufacturing | CP1: Pharmaceutical and Medicinal Product Manufacturing | CQ1: Other Basic Chemical Product Manufacturing | CR1: Beverage and Tobacco Product Manufacturing | CS1: Beverage Manufacturing | CT1: Fabricated Metal Product Manufacturing | CU1: Metal Container Manufacturing | CV1: Structural Metal Product Manufacturing | CW1: Other Fabricated Metal Product Manufacturing | CX1: Food Product Manufacturing | CY1: Bakery Product Manufacturing | CZ1: Dairy Product Manufacturing | DA1: Grain Mill and Cereal Product Manufacturing | DB1: Meat and Meat Product Manufacturing | DC1: Sugar and Confectionery Manufacturing | DD1: Other Food Product Manufacturing | DE1: Furniture and Other Manufacturing | DF1: Furniture Manufacturing | DG1: Other Manufacturing | DH1: Machinery and Equipment Manufacturing | DI1: Computer and Electronic Equipment Manufacturing | DJ1: Domestic Appliance Manufacturing | DK1: Electrical Equipment Manufacturing | DL1: Professional and Scientific Equipment Manufacturing | DM1: Pump, Compressor, Heating and Ventilation Equipment Manufacturing | DN1: Specialised Machinery and Equipment Manufacturing | DO1: Other Machinery and Equipment Manufacturing | DP1: Non-Metallic Mineral Product Manufacturing | DQ1: Cement, Lime, Plaster and Concrete Product Manufacturing | DR1: Ceramic Product Manufacturing | DS1: Petroleum and Coal Product Manufacturing | DT1: Polymer Product and Rubber Product Manufacturing | DU1: Polymer Product Manufacturing | DV1: Primary Metal and Metal Product Manufacturing | DW1: Basic Ferrous Metal Manufacturing | DX1: Basic Ferrous Metal Product Manufacturing | DY1: Basic Non-Ferrous Metal Manufacturing | DZ1: Basic Non-Ferrous Metal Product Manufacturing | EA1: Printing (including the Reproduction of Recorded Media) | EB1: Printing and Printing Support Services | EC1: Pulp, Paper and Converted Paper Product Manufacturing | ED1: Converted Paper Product Manufacturing | EE1: Textile, Leather, Clothing and Footwear Manufacturing | EF1: Clothing and Footwear Manufacturing | EG1: Textile Manufacturing | EH1: Textile Product Manufacturing | EI1: Transport Equipment Manufacturing | EJ1: Motor Vehicle and Motor Vehicle Part Manufacturing | EK1: Other Transport Equipment Manufacturing | EL1: Wood Product Manufacturing | EM1: Log Sawmilling and Timber Dressing | EN1: Other Wood Product Manufacturing | EO1: Mining | EP1: Exploration and Other Mining Support Services | EQ1: Exploration | ER1: Metal Ore Mining | ES1: Non-Metallic Mineral Mining and Quarrying | ET1: Construction Material Mining | EU1: Professional, Scientific and Technical Services | EV1: Professional, Scientific and Technical Services (Except Computer System Design and Related Services) | EW1: Architectural, Engineering and Technical Services | EX1: Legal and Accounting Services | EY1: Management and Related Consulting Services | EZ1: Other Professional, Scientific and Technical Services | FA1: Public Administration and Safety | FB1: Public Administration | FC1: Government Representation | FD1: Public Order, Safety and Regulatory Services | FE1: Public Order and Safety Services | FF1: Rental Hiring and Real Estate Services | FG1: Property Operators and Real Estate Services | FH1: Property Operators | FI1: Rental and Hiring Services (except Real Estate) | FJ1: Motor Vehicle and Transport Equipment Rental and Hiring | FK1: Other Goods and Equipment Rental and Hiring | FL1: Retail Trade | FM1: Food Retailing | FN1: Specialised Food Retailing | FO1: Motor Vehicle and Motor Vehicle Parts Retailing | FP1: Motor Vehicle Parts and Tyre Retailing | FQ1: Motor Vehicle Retailing | FR1: Non-Store Retailing and Retail Commission Based Buying and/or Selling | FS1: Other Store-Based Retailing | FT1: Clothing, Footwear and Personal Accessory Retailing | FU1: Electrical and Electronic Goods Retailing | FV1: Furniture, Floor Coverings, Houseware and Textile Goods Retailing | FW1: Hardware, Building and Garden Supplies Retailing | FX1: Pharmaceutical and Other Store-Based Retailing | FY1: Recreational Goods Retailing | FZ1: Transport, Postal and Warehousing | GA1: Postal and Courier Pick-up and Delivery Services | GB1: Rail Transport | GC1: Road Transport | GD1: Road Passenger Transport | GE1: Transport Support Services | GF1: Other Transport Support Services | GG1: Water Transport Support Services | GH1: Warehousing and Storage Services | GI1: Water Transport | GJ1: Other Transport | GK1: Pipeline and Other Transport | GL1: Wholesale Trade | GM1: Basic Material Wholesaling | GN1: Agricultural Product Wholesaling | GO1: Mineral, Metal and Chemical Wholesaling | GP1: Timber and Hardware Goods Wholesaling | GQ1: Grocery, Liquor and Tobacco Product Wholesaling | GR1: Machinery and Equipment Wholesaling | GS1: Specialised Industrial Machinery and Equipment Wholesaling | GT1: Other Machinery and Equipment Wholesaling | GU1: Motor Vehicle and Motor Vehicle Parts Wholesaling | GV1: Other Goods Wholesaling | GW1: Furniture, Floor Covering and Other Goods Wholesaling | GX1: Textile, Clothing and Footwear Wholesaling | GY1: Other Services | GZ1: Personal and Other Services | HA1: Civic Professional and Other Interest Group Services | HB1: Personal Care Services | HC1: Other Personal Services | HD1: Private Households Employing Staff and Undifferentiated Goods- and Service-Producing Activities of Households for Own Use | HE1: Repair and Maintenance | HF1: Automotive Repair and Maintenance | HG1: Machinery and Equipment Repair and Maintenance | HH1: Other Repair and Maintenance | HI1: Accommodation | HJ1: Contact persons email: | HK1: Accommodation

Sheet Industry Acronyms
A1: =Industry!A1 -> Timestamp | B1: =Industry!B1 -> Email | C1: =Industry!C1 -> Last Name | D1: =Industry!D1 -> First Name | E1: =Industry!E1 -> Industry | F1: =Industry!F1 -> Accommodation and Food Services | G1: =Industry!G1 -> Food and Beverage Services Group | H1: =Industry!H1 -> Cafes, Restaurants and Takeaway Food Services | ... HH1: =Industry!HH1 -> Other Repair and Maintenance | HI1: Accommodation | HJ1: Cafes, Restaurants and Takeaway Food Services | HK1: Clubs (Hospitality) | HL1: Pubs, Taverns and Bars | HM1: Employment Services | HN1: Travel Agency and Tour Arrangement Services | HO1: Other Administrative Services | HP1: Building Cleaning, Pest Control and Gardening Services | HQ1: Packaging Services | HR1: Dairy Cattle Farming | HS1: Deer Farming | HT1: Fruit and Tree Nut Growing | HU1: Mushroom and Vegetable Growing | HV1: Nursery and Floriculture Production | HW1: Poultry Farming | HX1: Sheep, Beef Cattle and Grain Farming | HY1: Other Crop Growing | HZ1: Other Livestock Farming | IA1: Agriculture and Fishing Support Services | IB1: Forestry Support Services | IC1: Aquaculture | ID1: Fishing | IE1: Hunting and Trapping | IF1: Forestry and Logging | IG1: Creative and Performing Arts Activities | IH1: Gambling Activities | II1: Museum Operation | IJ1: Parks and Gardens Operations | IK1: Amusement and Other Recreation Activities | IL1: Horse and Dog Racing Activities | IM1: Sports and Physical Recreation Activities | IN1: Residential Building Construction | IO1: Non-Residential Building Construction | IP1: Building Completion Services | IQ1: Building Installation Services | IR1: Building Structure Services | IS1: Land Development and Site Preparation Services | IT1: Other Construction Services | IU1: Road and Bridge Construction | IV1: Other Heavy and Civil Engineering Construction | IW1: Adult, Community and Other Education | IX1: Educational Support Services | IY1: Preschool Education | IZ1: School Education | JA1: Higher Education | JB1: Technical and Vocational Education and Training | JC1: Electricity Distribution | JD1: Electricity Generation | JE1: Electricity Transmission | JF1: On Selling Electricity and Electricity Market Operation | JG1: Gas Supply | JH1: Waste Collection Services | JI1: Waste Treatment, Disposal and Remediation Services | JJ1: Sewerage and Drainage Services | JK1: Water Supply | JL1: Auxiliary Finance and Investment Services | JM1: Auxiliary Insurance Services | JN1: Central Banking | JO1: Depository Financial Intermediation | JP1: Financial Asset Investing | JQ1: Non-Depository Financing | JR1: Health and General Insurance | JS1: Life Insurance | JT1: Superannuation Funds | JU1: Hospitals | JV1: Medical Services | JW1: Pathology and Diagnostic Imaging Services | JX1: Allied Health Services | JY1: Other Health Care Services | JZ1: Aged Care Residential Services | KA1: Other Residential Care Services | KB1: Child Care Services | KC1: Other Social Assistance Services | KD1: Radio Broadcasting | KE1: Television Broadcasting | KF1: Internet Publishing and Broadcasting | KG1: Data Processing, Web Hosting and Electronic Information Storage Services | KH1: Internet Service Providers and Web Search Portals | KI1: Libraries and Archives | KJ1: Other Information Services | KK1: Motion Picture and Video Activities | KL1: Sound Recording and Music Publishing | KM1: Newspaper, Periodical, Book and Directory Publishing | KN1: Software Publishing | KO1: Telecommunications Services | KP1: Basic Chemical Manufacturing | KQ1: Basic Polymer Manufacturing | KR1: Cleaning Compound and Toiletry Preparation Manufacturing | KS1: Fertiliser and Pesticide Manufacturing | KT1: Pharmaceutical and Medicinal Product Manufacturing | KU1: Other Basic Chemical Product Manufacturing | KV1: Beverage Manufacturing | KW1: Cigarette and Tobacco Product Manufacturing | KX1: Iron and Steel Forging | KY1: Metal Container Manufacturing | KZ1: Sheet Metal Product Manufacturing (except Metal Structural and Container Products) | LA1: Structural Metal Product Manufacturing | LB1: Other Fabricated Metal Product Manufacturing | LC1: Bakery Product Manufacturing | LD1: Dairy Product Manufacturing | LE1: Fruit and Vegetable Processing | LF1: Grain Mill and Cereal Product Manufacturing | LG1: Meat and Meat Product Manufacturing | LH1: Oil and Fat Manufacturing | LI1: Seafood Processing | LJ1: Sugar and Confectionery Manufacturing | LK1: Other Food Product Manufacturing | LL1: Furniture Manufacturing | LM1: Other Manufacturing | LN1: Computer and Electronic Equipment Manufacturing | LO1: Domestic Appliance Manufacturing | LP1: Electrical Equipment Manufacturing | LQ1: Professional and Scientific Equipment Manufacturing | LR1: Pump, Compressor, Heating and Ventilation Equipment Manufacturing | LS1: Specialised Machinery and Equipment Manufacturing | LT1: Other Machinery and Equipment Manufacturing | LU1: Cement, Lime, Plaster and Concrete Product Manufacturing | LV1: Ceramic Product Manufacturing | LW1: Glass and Glass Product Manufacturing | LX1: Other Non-Metallic Mineral Product Manufacturing | LY1: Petroleum Refining and Petroleum Fuel Manufacturing | LZ1: Other Petroleum and Coal Product Manufacturing | MA1: Natural Rubber Product Manufacturing | MB1: Polymer Product Manufacturing | MC1: Basic Ferrous Metal Manufacturing | MD1: Basic Ferrous Metal Product Manufacturing | ME1: Basic Non-Ferrous Metal Manufacturing | MF1: Basic Non-Ferrous Metal Product Manufacturing | MG1: Printing and Printing Support Services | MH1: Reproduction of Recorded Media | MI1: Converted Paper Product Manufacturing | MJ1: Pulp, Paper and Paperboard Manufacturing | MK1: Clothing and Footwear Manufacturing | ML1: Knitted Product Manufacturing | MM1: Leather Tanning, Fur Dressing and Leather Product Manufacturing | MN1: Textile Manufacturing | MO1: Textile Product Manufacturing | MP1: Motor Vehicle and Motor Vehicle Part Manufacturing | MQ1: Other Transport Equipment Manufacturing | MR1: Log Sawmilling and Timber Dressing | MS1: Other Wood Product Manufacturing | MT1: Coal Mining | MU1: Exploration | MV1: Other Mining Support Services | MW1: Metal Ore Mining | MX1: Construction Material Mining | MY1: Oil and Gas Extraction | MZ1: Other Non-Metallic Mineral Mining and Quarrying | NA1: Computer System Design and Related Services | NB1: Advertising Services | NC1: Architectural, Engineering and Technical Services | ND1: Legal and Accounting Services | NE1: Management and Related Consulting Services | NF1: Market Research and Statistical Services | NG1: Scientific Research Services | NH1: Veterinary Services | NI1: Other Professional, Scientific and Technical Services | NJ1: Central Government Administration | NK1: State Government Administration | NL1: Local Government Administration | NM1: Justice | NN1: Government Representation | NO1: Defence | NP1: Public Order and Safety Services | NQ1: Regulatory Services | NR1: Property Operators | NS1: Real Estate Services | NT1: Farm Animal and Bloodstock Leasing | NU1: Motor Vehicle and Transport Equipment Rental and Hiring | NV1: Non-Financial Intangible Assets (Except Copyrights) Leasing | NW1: Other Goods and Equipment Rental and Hiring | NX1: Supermarket and Grocery Stores | NY1: Specialised Food Retailing | NZ1: Fuel Retailing | OA1: Motor Vehicle Parts and Tyre Retailing | OB1: Motor Vehicle Retailing | OC1: Non-Store Retailing | OD1: Retail Commission-Based Buying and/or Selling | OE1: Clothing, Footwear and Personal Accessory Retailing | OF1: Department Stores | OG1: Electrical and Electronic Goods Retailing | OH1: Furniture, Floor Coverings, Houseware and Textile Goods Retailing | OI1: Hardware, Building and Garden Supplies Retailing | OJ1: Pharmaceutical and Other Store-Based Retailing | OK1: Recreational Goods Retailing | OL1: Air and Space Transport | OM1: Postal and Courier Pick-up and Delivery Services | ON1: Rail Freight Transport | OO1: Rail Passenger Transport | OP1: Road Freight Transport | OQ1: Road Passenger Transport | OR1: Airport Operations and Other Air Transport Support Services | OS1: Water Transport Support Services | OT1: Other Transport Support Services | OU1: Warehousing and Storage Services | OV1: Water Freight Transport | OW1: Water Passenger Transport | OX1: Pipeline and Other Transport | OY1: Scenic and Sightseeing Transport | OZ1: Agricultural Product Wholesaling | PA1: Mineral, Metal and Chemical Wholesaling | PB1: Timber and Hardware Goods Wholesaling | PC1: Commission-Based Wholesaling | PD1: Grocery, Liquor and Tobacco Product Wholesaling | PE1: Specialised Industrial Machinery and Equipment Wholesaling | PF1: Other Machinery and Equipment Wholesaling | PG1: Motor Vehicle and Motor Vehicle Parts Wholesaling | PH1: Textile, Clothing and Footwear Wholesaling | PI1: Furniture, Floor Covering and Other Goods Wholesaling | PJ1: Pharmaceutical and Toiletry Goods Wholesaling | PK1: Civic, Professional and Other Interest Group Services | PL1: Funeral, Crematorium and Cemetery Services | PM1: Personal Care Services | PN1: Religious Services | PO1: Other Personal Services | PP1: Private Households Employing Staff and Undifferentiated Goods- and Service-Producing Activities of Households for Own Use | PQ1: Automotive Repair and Maintenance | PR1: Machinery and Equipment Repair and Maintenance | PS1: Other Repair and Maintenance
HI2: =if(ISERROR(SEARCH("Accommodation",F2)),"","440") | HJ2: =if(ISERROR(SEARCH("Cafes, Restaurants and Takeaway Food Services",G2)),"","450") | HK2: =if(ISERROR(SEARCH("Clubs (Hospitality)",G2)),"","453") | HL2: =if(ISERROR(SEARCH("Pubs, Taverns and Bars",G2)),"","452") | HM2: =if(ISERROR(SEARCH("Employment Services",J2)),"","721") | HN2: =if(ISERROR(SEARCH("Travel Agency and Tour Arrangement Services",J2)),"","722") | HO2: =if(ISERROR(SEARCH("Other Administrative Services",J2)),"","729") | HP2: =if(ISERROR(SEARCH("Building Cleaning, Pest Control and Gardening Servicess",M2)),"","731") | HQ2: =if(ISERROR(SEARCH("Packaging Services",M2)),"","732") | HR2: =if(ISERROR(SEARCH("Dairy Cattle Farming",P2)),"","016") | HS2: =if(ISERROR(SEARCH("Deer Farming",P2)),"","018") | HT2: =if(ISERROR(SEARCH("Fruit and Tree Nut Growing",P2)),"","013") | HU2: =if(ISERROR(SEARCH("Mushroom and Vegetable Growing",P2)),"","012") | HV2: =if(ISERROR(SEARCH("Nursery and Floriculture Production",P2)),"","011") | HW2: =if(ISERROR(SEARCH("Poultry Farming",P2)),"","017") | HX2: =if(ISERROR(SEARCH("Sheep, Beef Cattle and Grain Farming",P2)),"","014") | HY2: =if(ISERROR(SEARCH("Other Crop Growing",P2)),"","015") | HZ2: =if(ISERROR(SEARCH("Other Livestock Farming",P2)),"","019") | IA2: =if(ISERROR(SEARCH("Agriculture and Fishing Support Services",X2)),"","052") | IB2: =if(ISERROR(SEARCH("Forestry Support Services",X2)),"","051") | IC2: =if(ISERROR(SEARCH("Aquaculture",Z2)),"","020") | ID2: =if(ISERROR(SEARCH("Fishing",AA2)),"","041") | IE2: =if(ISERROR(SEARCH("Hunting and Trapping",AA2)),"","042") | IF2: =if(ISERROR(SEARCH("Forestry and Logging",AB2)),"","030") | IG2: =if(ISERROR(SEARCH("Creative and Performing Arts Activities",AD2)),"","900") | IH2: =if(ISERROR(SEARCH("Gambling Activities",AD2)),"","920") | II2: =if(ISERROR(SEARCH("Museum Operation",AG2)),"","891") | IJ2: =if(ISERROR(SEARCH("Parks and Gardens Operations",AG2)),"","892") | IK2: =if(ISERROR(SEARCH("Amusement and Other Recreation Activities",AI2)),"","913") | IL2: =if(ISERROR(SEARCH("Horse and Dog Racing Activities",AI2)),"","912") | IM2: =if(ISERROR(SEARCH("Sports and Physical Recreation Activities",AI2)),"","911") | IN2: =if(ISERROR(SEARCH("Residential Building Construction",AN2)),"","301") | IO2: =if(ISERROR(SEARCH("Non-Residential Building Construction",AN2)),"","302") | IP2: =if(ISERROR(SEARCH("Building Completion Services",AP2)),"","324") | IQ2: =if(ISERROR(SEARCH("Building Installation Servicess",AP2)),"","323") | IR2: =if(ISERROR(SEARCH("Building Structure Services",AP2)),"","322") | IS2: =if(ISERROR(SEARCH("Land Development and Site Preparation Services",AP2)),"","321") | IT2: =if(ISERROR(SEARCH("Other Construction Services",AP2)),"","329") | IU2: =if(ISERROR(SEARCH("Road and Bridge Construction",AV2)),"","310") | IV2: =if(ISERROR(SEARCH("Other Heavy and Civil Engineering Construction",AV2)),"","310") | IW2: =if(ISERROR(SEARCH("Adult, Community and Other Education",AX2)),"","821") | IX2: =if(ISERROR(SEARCH("Educational Support Services",AX2)),"","822") | IY2: =if(ISERROR(SEARCH("Preschool Education",AZ2)),"","801") | IZ2: =if(ISERROR(SEARCH("School Education",AZ2)),"","802") | JA2: =if(ISERROR(SEARCH("Higher Education",BB2)),"","810") | JB2: =if(ISERROR(SEARCH("Higher Education",BC2)),"","810") | JC2: =if(ISERROR(SEARCH("Electricity Distribution",BC2)),"","263") | JD2: =if(ISERROR(SEARCH("Electricity Generation",BC2)),"","261") | JE2: =if(ISERROR(SEARCH("Electricity Transmission",BC2)),"","262") | JF2: =if(ISERROR(SEARCH("On Selling Electricity and Electricity Market Operation",BC2)),"","264") | JG2: =if(ISERROR(SEARCH("Gas Supply",BC2)),"","270") | JH2: =if(ISERROR(SEARCH("Waste Collection Services",BF2)),"","291") | JI2: =if(ISERROR(SEARCH("Waste Treatment, Disposal and Remediation Services",BF2)),"","292") | JJ2: =if(ISERROR(SEARCH("Sewerage and Drainage Services",BI2)),"","281") | JK2: =if(ISERROR(SEARCH("Water Supply",BI2)),"","281") | JL2: =if(ISERROR(SEARCH("Auxiliary Finance and Investment Services",BK2)),"","641") | JM2: =if(ISERROR(SEARCH("Auxiliary Insurance Services",BK2)),"","642") | JN2: =if(ISERROR(SEARCH("Central Banking",BM2)),"","621") | JO2: =if(ISERROR(SEARCH("Depository Financial Intermediation",BM2)),"","622") | JP2: =if(ISERROR(SEARCH("Financial Asset Investing",BM2)),"","624") | JQ2: =if(ISERROR(SEARCH("Non-Depository Financing",BM2)),"","623") | JR2: =if(ISERROR(SEARCH("Health and General Insurance",BO2)),"","632") | JS2: =if(ISERROR(SEARCH("Life Insurance",BO2)),"","631") | JT2: =if(ISERROR(SEARCH("Superannuation Funds",BO2)),"","633") | JU2: =if(ISERROR(SEARCH("Hospitals",BQ2)),"","840") | JV2: =if(ISERROR(SEARCH("Medical Services",BS2)),"","851") | JW2: =if(ISERROR(SEARCH("Pathology and Diagnostic Imaging Services",BS2)),"","852") | JX2: =if(ISERROR(SEARCH("Allied Health Services",BS2)),"","853") | JY2: =if(ISERROR(SEARCH("Other Health Care Services",BS2)),"","859") | JZ2: =if(ISERROR(SEARCH("Aged Care Residential Services",BW2)),"","860") | KA2: =if(ISERROR(SEARCH("Other Residential Care Services",BW2)),"","860") | KB2: =if(ISERROR(SEARCH("Child Care Services",BX2)),"","871") | KC2: =if(ISERROR(SEARCH("Other Social Assistance Services",BX2)),"","879") | KD2: =if(ISERROR(SEARCH("Radio Broadcasting",BZ2)),"","561") | KE2: =if(ISERROR(SEARCH("Television Broadcasting",BZ2)),"","562") | KF2: =if(ISERROR(SEARCH("Internet Publishing and Broadcasting",BY2)),"","570") | KG2: =if(ISERROR(SEARCH("Data Processing, Web Hosting and Electronic Information Storage Services",CB2)),"","592") | KH2: =if(ISERROR(SEARCH("Internet Service Providers and Web Search Portals",CB2)),"","591") | KI2: =if(ISERROR(SEARCH("Libraries and Archives",CD2)),"","601") | KJ2: =if(ISERROR(SEARCH("Other Information Services",CD2)),"","602") | KK2: =if(ISERROR(SEARCH("Motion Picture and Video Activities",CE2)),"","551") | KL2: =if(ISERROR(SEARCH("Sound Recording and Music Publishing",CE2)),"","552") | KM2: =if(ISERROR(SEARCH("Newspaper, Periodical, Book and Directory Publishing",CH2)),"","541") | KN2: =if(ISERROR(SEARCH("Software Publishing",CH2)),"","542") | KO2: =if(ISERROR(SEARCH("Telecommunications Services",BY2)),"","580") | KP2: =if(ISERROR(SEARCH("Basic Chemical Manufacturing",CK2)),"","181") | KQ2: =if(ISERROR(SEARCH("Basic Polymer Manufacturing",CK2)),"","182") | KR2: =if(ISERROR(SEARCH("Cleaning Compound and Toiletry Preparation Manufacturing",CK2)),"","185") | KS2: =if(ISERROR(SEARCH("Fertiliser and Pesticide Manufacturing",CK2)),"","183") | KT2: =if(ISERROR(SEARCH("Pharmaceutical and Medicinal Product Manufacturing",CK2)),"","184") | KU2: =if(ISERROR(SEARCH("Other Basic Chemical Product Manufacturing",CK2)),"","189") | KV2: =if(ISERROR(SEARCH("Beverage Manufacturing",CR2)),"","121") | KW2: =if(ISERROR(SEARCH("Cigarette and Tobacco Product Manufacturing",CR2)),"","122") | KX2: =if(ISERROR(SEARCH("Iron and Steel Forging",CT2)),"","221") | KY2: =if(ISERROR(SEARCH("Metal Container Manufacturing",CT2)),"","223") | KZ2: =if(ISERROR(SEARCH("Sheet Metal Product Manufacturing (except Metal Structural and Container Products)",CT2)),"","224") | LA2: =if(ISERROR(SEARCH("Structural Metal Product Manufacturing",CT2)),"","222") | LB2: =if(ISERROR(SEARCH("Other Fabricated Metal Product Manufacturing",CT2)),"","229") | LC2: =if(ISERROR(SEARCH("Bakery Product Manufacturing",CX2)),"","117") | LD2: =if(ISERROR(SEARCH("Dairy Product Manufacturing",CX2)),"","113") | LE2: =if(ISERROR(SEARCH("Fruit and Vegetable Processing",CX2)),"","114") | LF2: =if(ISERROR(SEARCH("Grain Mill and Cereal Product Manufacturing",CX2)),"","116") | LG2: =if(ISERROR(SEARCH("Meat and Meat Product Manufacturing",CX2)),"","111") | LH2: =if(ISERROR(SEARCH("Oil and Fat Manufacturing",CX2)),"","115") | LI2: =if(ISERROR(SEARCH("Seafood Processing",CX2)),"","112") | LJ2: =if(ISERROR(SEARCH("Sugar and Confectionery Manufacturing",CX2)),"","118") | LK2: =if(ISERROR(SEARCH("Other Food Product Manufacturing",CX2)),"","119") | LL2: =if(ISERROR(SEARCH("Furniture Manufacturing",DE2)),"","251") | LM2: =if(ISERROR(SEARCH("Other Manufacturing",DE2)),"","259") | LN2: =if(ISERROR(SEARCH("Computer and Electronic Equipment Manufacturing",DH2)),"","242") | LO2: =if(ISERROR(SEARCH("Domestic Appliance Manufacturing",DH2)),"","244") | LP2: =if(ISERROR(SEARCH("Electrical Equipment Manufacturing",DH2)),"","243") | LQ2: =if(ISERROR(SEARCH("Professional and Scientific Equipment Manufacturing",DH2)),"","241") | LR2: =if(ISERROR(SEARCH("Pump, Compressor, Heating and Ventilation Equipment Manufacturing",DH2)),"","245") | LS2: =if(ISERROR(SEARCH("Specialised Machinery and Equipment Manufacturing",DH2)),"","246") | LT2: =if(ISERROR(SEARCH("Other Machinery and Equipment Manufacturing",DH2)),"","249") | LU2: =if(ISERROR(SEARCH("Cement, Lime, Plaster and Concrete Product Manufacturing",DP2)),"","203") | LV2: =if(ISERROR(SEARCH("Ceramic Product Manufacturing",DP2)),"","202") | LW2: =if(ISERROR(SEARCH("Glass and Glass Product Manufacturing",DP2)),"","201") | LX2: =if(ISERROR(SEARCH("Other Non-Metallic Mineral Product Manufacturing",DP2)),"","209") | LY2: =if(ISERROR(SEARCH("Petroleum Refining and Petroleum Fuel Manufacturing",DS2)),"","170") | LZ2: =if(ISERROR(SEARCH("Other Petroleum and Coal Product Manufacturing",DS2)),"","170") | MA2: =if(ISERROR(SEARCH("Natural Rubber Product Manufacturing",DT2)),"","192") | MB2: =if(ISERROR(SEARCH("Polymer Product Manufacturing",DT2)),"","191") | MC2: =if(ISERROR(SEARCH("Basic Ferrous Metal Manufacturing",DV2)),"","211") | MD2: =if(ISERROR(SEARCH("Basic Ferrous Metal Product Manufacturing",DV2)),"","212") | ME2: =if(ISERROR(SEARCH("Basic Non-Ferrous Metal Manufacturing",DV2)),"","213") | MF2: =if(ISERROR(SEARCH("Basic Non-Ferrous Metal Product Manufacturing",DV2)),"","214") | MG2: =if(ISERROR(SEARCH("Printing and Printing Support Services",EA2)),"","161") | MH2: =if(ISERROR(SEARCH("Reproduction of Recorded Media",EA2)),"","162") | MI2: =if(ISERROR(SEARCH("Converted Paper Product Manufacturing",EC2)),"","152") | MJ2: =if(ISERROR(SEARCH("Pulp, Paper and Paperboard Manufacturing",EC2)),"","151") | MK2: =if(ISERROR(SEARCH("Clothing and Footwear Manufacturing",EE2)),"","135") | ML2: =if(ISERROR(SEARCH("Knitted Product Manufacturing",EE2)),"","134") | MM2: =if(ISERROR(SEARCH("Leather Tanning, Fur Dressing and Leather Product Manufacturing",EE2)),"","132") | MN2: =if(ISERROR(SEARCH("Textile Manufacturing",EE2)),"","131") | MO2: =if(ISERROR(SEARCH("Textile Product Manufacturing",EE2)),"","133") | MP2: =if(ISERROR(SEARCH("Motor Vehicle and Motor Vehicle Part Manufacturing",EI2)),"","231") | MQ2: =if(ISERROR(SEARCH("Other Transport Equipment Manufacturing",EI2)),"","239") | MR2: =if(ISERROR(SEARCH("Log Sawmilling and Timber Dressing",EL2)),"","141") | MS2: =if(ISERROR(SEARCH("Other Wood Product Manufacturing",EL2)),"","149") | MT2: =if(ISERROR(SEARCH("Coal Mining",EO2)),"","060") | MU2: =if(ISERROR(SEARCH("Exploration",EP2)),"","101") | MV2: =if(ISERROR(SEARCH("Other Mining Support Services",EP2)),"","109") | MW2: =if(ISERROR(SEARCH("Metal Ore Mining",EO2)),"","080") | MX2: =if(ISERROR(SEARCH("Construction Material Mining",ES2)),"","091") | MY2: =if(ISERROR(SEARCH("Oil and Gas Extraction",EO2)),"","070") | MZ2: =if(ISERROR(SEARCH("Other Non-Metallic Mineral Mining and Quarrying",ES2)),"","099") | NA2: =if(ISERROR(SEARCH("Computer System Design and Related Services",EU2)),"","700") | NB2: =if(ISERROR(SEARCH("Advertising Services",EV2)),"","694") | NC2: =if(ISERROR(SEARCH("Architectural, Engineering and Technical Services",EV2)),"","692") | ND2: =if(ISERROR(SEARCH("Legal and Accounting Services",EV2)),"","693") | NE2: =if(ISERROR(SEARCH("Management and Related Consulting Services",EV2)),"","696") | NF2: =if(ISERROR(SEARCH("Market Research and Statistical Services",EV2)),"","695") | NG2: =if(ISERROR(SEARCH("Scientific Research Services",EV2)),"","691") | NH2: =if(ISERROR(SEARCH("Veterinary Services",EV2)),"","697") | NI2: =if(ISERROR(SEARCH("Other Professional, Scientific and Technical Services",EV2)),"","699") | NJ2: =if(ISERROR(SEARCH("Central Government Administration",FB2)),"","751") | NK2: =if(ISERROR(SEARCH("State Government Administration",FB2)),"","752") | NL2: =if(ISERROR(SEARCH("Local Government Administration",FB2)),"","753") | NM2: =if(ISERROR(SEARCH("Justice",FB2)),"","754") | NN2: =if(ISERROR(SEARCH("Government Representation",FB2)),"","755") | NO2: =if(ISERROR(SEARCH("Defence",FA2)),"","760") | NP2: =if(ISERROR(SEARCH("Public Order and Safety Services",FD2)),"","771") | NQ2: =if(ISERROR(SEARCH("Regulatory Services",FD2)),"","772") | NR2: =if(ISERROR(SEARCH("Property Operators",FG2)),"","671") | NS2: =if(ISERROR(SEARCH("Real Estate Services",FG2)),"","672") | NT2: =if(ISERROR(SEARCH("Farm Animal and Bloodstock Leasing",FI2)),"","662") | NU2: =if(ISERROR(SEARCH("Motor Vehicle and Transport Equipment Rental and Hiring",FI2)),"","661") | NV2: =if(ISERROR(SEARCH("Non-Financial Intangible Assets (Except Copyrights) Leasing",FI2)),"","664") | NW2: =if(ISERROR(SEARCH("Other Goods and Equipment Rental and Hiring",FI2)),"","663") | NX2: =if(ISERROR(SEARCH("Supermarket and Grocery Stores",FM2)),"","411") | NY2: =if(ISERROR(SEARCH("Specialised Food Retailing",FM2)),"","412") | NZ2: =if(ISERROR(SEARCH("Fuel Retailing",FL2)),"","400") | OA2: =if(ISERROR(SEARCH("Motor Vehicle Parts and Tyre Retailing",FO2)),"","392") | OB2: =if(ISERROR(SEARCH("Motor Vehicle Retailing",FO2)),"","391") | OC2: =if(ISERROR(SEARCH("Non-Store Retailing",FR2)),"","431") | OD2: =if(ISERROR(SEARCH("Retail Commission-Based Buying and/or Selling",FR2)),"","432") | OE2: =if(ISERROR(SEARCH("Clothing, Footwear and Personal Accessory Retailing",FS2)),"","425") | OF2: =if(ISERROR(SEARCH("Department Stores",FS2)),"","426") | OG2: =if(ISERROR(SEARCH("Electrical and Electronic Goods Retailing",FS2)),"","422") | OH2: =if(ISERROR(SEARCH("Furniture, Floor Coverings, Houseware and Textile Goods Retailing",FS2)),"","421") | OI2: =if(ISERROR(SEARCH("Hardware, Building and Garden Supplies Retailing",FS2)),"","423") | OJ2: =if(ISERROR(SEARCH("Pharmaceutical and Other Store-Based Retailing",FS2)),"","427") | OK2: =if(ISERROR(SEARCH("Recreational Goods Retailing",FS2)),"","424") | OL2: =if(ISERROR(SEARCH("Air and Space Transport",FZ2)),"","490") | OM2: =if(ISERROR(SEARCH("Postal and Courier Pick-up and Delivery Services",FZ2)),"","510") | ON2: =if(ISERROR(SEARCH("Rail Freight Transport",GB2)),"","471") | OO2: =if(ISERROR(SEARCH("Rail Passenger Transport",GB2)),"","472") | OP2: =if(ISERROR(SEARCH("Road Freight Transport",GC2)),"","461") | OQ2: =if(ISERROR(SEARCH("Road Passenger Transport",GC2)),"","462") | OR2: =if(ISERROR(SEARCH("Airport Operations and Other Air Transport Support Services",GE2)),"","522") | OS2: =if(ISERROR(SEARCH("Water Transport Support Services",GE2)),"","521") | OT2: =if(ISERROR(SEARCH("Other Transport Support Services",GE2)),"","529") | OU2: =if(ISERROR(SEARCH("Warehousing and Storage Services",FZ2)),"","530") | OV2: =if(ISERROR(SEARCH("Water Freight Transport",GI2)),"","481") | OW2: =if(ISERROR(SEARCH("Water Freight Transport",GI2)),"","482") | OX2: =if(ISERROR(SEARCH("Pipeline and Other Transport",GJ2)),"","502") | OY2: =if(ISERROR(SEARCH("Scenic and Sightseeing Transport",GJ2)),"","501") | OZ2: =if(ISERROR(SEARCH("Agricultural Product Wholesaling",GM2)),"","331") | PA2: =if(ISERROR(SEARCH("Mineral, Metal and Chemical Wholesaling",GM2)),"","332") | PB2: =if(ISERROR(SEARCH("Timber and Hardware Goods Wholesaling",GM2)),"","333") | PC2: =if(ISERROR(SEARCH("Commission-Based Wholesaling",GL2)),"","380") | PD2: =if(ISERROR(SEARCH("Grocery, Liquor and Tobacco Product Wholesaling",GL2)),"","360") | PE2: =if(ISERROR(SEARCH("Specialised Industrial Machinery and Equipment Wholesaling",GR2)),"","341") | PF2: =if(ISERROR(SEARCH("Other Machinery and Equipment Wholesaling",GR2)),"","349") | PG2: =if(ISERROR(SEARCH("Motor Vehicle and Motor Vehicle Parts Wholesaling",GL2)),"","350") | PH2: =if(ISERROR(SEARCH("Textile, Clothing and Footwear Wholesaling",GV2)),"","371") | PI2: =if(ISERROR(SEARCH("Furniture, Floor Covering and Other Goods Wholesaling",GV2)),"","373") | PJ2: =if(ISERROR(SEARCH("Pharmaceutical and Toiletry Goods Wholesaling",GV2)),"","372") | PK2: =if(ISERROR(SEARCH("Civic, Professional and Other Interest Group Services",GZ2)),"","955") | PL2: =if(ISERROR(SEARCH("Funeral, Crematorium and Cemetery Services",GZ2)),"","952") | PM2: =if(ISERROR(SEARCH("Personal Care Services",GZ2)),"","951") | PN2: =if(ISERROR(SEARCH("Religious Services",GZ2)),"","954") | PO2: =if(ISERROR(SEARCH("Other Personal Services",GZ2)),"","953") | PP2: =if(ISERROR(SEARCH("Private Households Employing Staff and Undifferentiated Goods- and Service-Producing Activities of Households for Own Use",GY2)),"","960") | PQ2: =if(ISERROR(SEARCH("Automotive Repair and Maintenance",HE2)),"","941") | PR2: =if(ISERROR(SEARCH("Machinery and Equipment Repair and Maintenance",HE2)),"","942") | PS2: =if(ISERROR(SEARCH("Other Repair and Maintenance",HE2)),"","949")
HI3: =if(ISERROR(SEARCH("Accommodation",F3)),"","440") | HJ3: =if(ISERROR(SEARCH("Cafes, Restaurants and Takeaway Food Services",G3)),"","450") | HK3: =if(ISERROR(SEARCH("Clubs (Hospitality)",G3)),"","453") | HL3: =if(ISERROR(SEARCH("Pubs, Taverns and Bars",G3)),"","452") | HM3: =if(ISERROR(SEARCH("Employment Services",J3)),"","721") | HN3: =if(ISERROR(SEARCH("Travel Agency and Tour Arrangement Services",J3)),"","722") | HO3: =if(ISERROR(SEARCH("Other Administrative Services",J3)),"","729") | HP3: =if(ISERROR(SEARCH("Building Cleaning, Pest Control and Gardening Servicess",M3)),"","731") | HQ3: =if(ISERROR(SEARCH("Packaging Services",M3)),"","732") | HR3: =if(ISERROR(SEARCH("Dairy Cattle Farming",P3)),"","016") | HS3: =if(ISERROR(SEARCH("Deer Farming",P3)),"","018") | HT3: =if(ISERROR(SEARCH("Fruit and Tree Nut Growing",P3)),"","013") | HU3: =if(ISERROR(SEARCH("Mushroom and Vegetable Growing",P3)),"","012") | HV3: =if(ISERROR(SEARCH("Nursery and Floriculture Production",P3)),"","011") | HW3: =if(ISERROR(SEARCH("Poultry Farming",P3)),"","017") | HX3: =if(ISERROR(SEARCH("Sheep, Beef Cattle and Grain Farming",P3)),"","014") | HY3: =if(ISERROR(SEARCH("Other Crop Growing",P3)),"","015") | HZ3: =if(ISERROR(SEARCH("Other Livestock Farming",P3)),"","019") | IA3: =if(ISERROR(SEARCH("Agriculture and Fishing Support Services",X3)),"","052") | IB3: =if(ISERROR(SEARCH("Forestry Support Services",X3)),"","051") | IC3: =if(ISERROR(SEARCH("Aquaculture",Z3)),"","020") | ID3: =if(ISERROR(SEARCH("Fishing",AA3)),"","041") | IE3: =if(ISERROR(SEARCH("Hunting and Trapping",AA3)),"","042") | IF3: =if(ISERROR(SEARCH("Forestry and Logging",AB3)),"","030") | IG3: =if(ISERROR(SEARCH("Creative and Performing Arts Activities",AD3)),"","900") | IH3: =if(ISERROR(SEARCH("Gambling Activities",AD3)),"","920") | II3: =if(ISERROR(SEARCH("Museum Operation",AG3)),"","891") | IJ3: =if(ISERROR(SEARCH("Parks and Gardens Operations",AG3)),"","892") | IK3: =if(ISERROR(SEARCH("Amusement and Other Recreation Activities",AI3)),"","913") | IL3: =if(ISERROR(SEARCH("Horse and Dog Racing Activities",AI3)),"","912") | IM3: =if(ISERROR(SEARCH("Sports and Physical Recreation Activities",AI3)),"","911") | IN3: =if(ISERROR(SEARCH("Residential Building Construction",AN3)),"","301") | IO3: =if(ISERROR(SEARCH("Non-Residential Building Construction",AN3)),"","302") | IP3: =if(ISERROR(SEARCH("Building Completion Services",AP3)),"","324") | IQ3: =if(ISERROR(SEARCH("Building Installation Servicess",AP3)),"","323") | IR3: =if(ISERROR(SEARCH("Building Structure Services",AP3)),"","322") | IS3: =if(ISERROR(SEARCH("Land Development and Site Preparation Services",AP3)),"","321") | IT3: =if(ISERROR(SEARCH("Other Construction Services",AP3)),"","329") | IU3: =if(ISERROR(SEARCH("Road and Bridge Construction",AV3)),"","310") | IV3: =if(ISERROR(SEARCH("Other Heavy and Civil Engineering Construction",AV3)),"","310") | IW3: =if(ISERROR(SEARCH("Adult, Community and Other Education",AX3)),"","821") | IX3: =if(ISERROR(SEARCH("Educational Support Services",AX3)),"","822") | IY3: =if(ISERROR(SEARCH("Preschool Education",AZ3)),"","801") | IZ3: =if(ISERROR(SEARCH("School Education",AZ3)),"","802") | JA3: =if(ISERROR(SEARCH("Higher Education",BB3)),"","810") | JB3: =if(ISERROR(SEARCH("Higher Education",BC3)),"","810") | JC3: =if(ISERROR(SEARCH("Electricity Distribution",BC3)),"","263") | JD3: =if(ISERROR(SEARCH("Electricity Generation",BC3)),"","261") | JE3: =if(ISERROR(SEARCH("Electricity Transmission",BC3)),"","262") | JF3: =if(ISERROR(SEARCH("On Selling Electricity and Electricity Market Operation",BC3)),"","264") | JG3: =if(ISERROR(SEARCH("Gas Supply",BC3)),"","270") | JH3: =if(ISERROR(SEARCH("Waste Collection Services",BF3)),"","291") | JI3: =if(ISERROR(SEARCH("Waste Treatment, Disposal and Remediation Services",BF3)),"","292") | JJ3: =if(ISERROR(SEARCH("Sewerage and Drainage Services",BI3)),"","281") | JK3: =if(ISERROR(SEARCH("Water Supply",BI3)),"","281") | JL3: =if(ISERROR(SEARCH("Auxiliary Finance and Investment Services",BK3)),"","641") | JM3: =if(ISERROR(SEARCH("Auxiliary Insurance Services",BK3)),"","642") | JN3: =if(ISERROR(SEARCH("Central Banking",BM3)),"","621") | JO3: =if(ISERROR(SEARCH("Depository Financial Intermediation",BM3)),"","622") | JP3: =if(ISERROR(SEARCH("Financial Asset Investing",BM3)),"","624") | JQ3: =if(ISERROR(SEARCH("Non-Depository Financing",BM3)),"","623") | JR3: =if(ISERROR(SEARCH("Health and General Insurance",BO3)),"","632") | JS3: =if(ISERROR(SEARCH("Life Insurance",BO3)),"","631") | JT3: =if(ISERROR(SEARCH("Superannuation Funds",BO3)),"","633") | JU3: =if(ISERROR(SEARCH("Hospitals",BQ3)),"","840") | JV3: =if(ISERROR(SEARCH("Medical Services",BS3)),"","851") | JW3: =if(ISERROR(SEARCH("Pathology and Diagnostic Imaging Services",BS3)),"","852") | JX3: =if(ISERROR(SEARCH("Allied Health Services",BS3)),"","853") | JY3: =if(ISERROR(SEARCH("Other Health Care Services",BS3)),"","859") | JZ3: =if(ISERROR(SEARCH("Aged Care Residential Services",BW3)),"","860") | KA3: =if(ISERROR(SEARCH("Other Residential Care Services",BW3)),"","860") | KB3: =if(ISERROR(SEARCH("Child Care Services",BX3)),"","871") | KC3: =if(ISERROR(SEARCH("Other Social Assistance Services",BX3)),"","879") | KD3: =if(ISERROR(SEARCH("Radio Broadcasting",BZ3)),"","561") | KE3: =if(ISERROR(SEARCH("Television Broadcasting",BZ3)),"","562") | KF3: =if(ISERROR(SEARCH("Internet Publishing and Broadcasting",BY3)),"","570") | KG3: =if(ISERROR(SEARCH("Data Processing, Web Hosting and Electronic Information Storage Services",CB3)),"","592") | KH3: =if(ISERROR(SEARCH("Internet Service Providers and Web Search Portals",CB3)),"","591") | KI3: =if(ISERROR(SEARCH("Libraries and Archives",CD3)),"","601") | KJ3: =if(ISERROR(SEARCH("Other Information Services",CD3)),"","602") | KK3: =if(ISERROR(SEARCH("Motion Picture and Video Activities",CE3)),"","551") | KL3: =if(ISERROR(SEARCH("Sound Recording and Music Publishing",CE3)),"","552") | KM3: =if(ISERROR(SEARCH("Newspaper, Periodical, Book and Directory Publishing",CH3)),"","541") | KN3: =if(ISERROR(SEARCH("Software Publishing",CH3)),"","542") | KO3: =if(ISERROR(SEARCH("Telecommunications Services",BY3)),"","580") | KP3: =if(ISERROR(SEARCH("Basic Chemical Manufacturing",CK3)),"","181") | KQ3: =if(ISERROR(SEARCH("Basic Polymer Manufacturing",CK3)),"","182") | KR3: =if(ISERROR(SEARCH("Cleaning Compound and Toiletry Preparation Manufacturing",CK3)),"","185") | KS3: =if(ISERROR(SEARCH("Fertiliser and Pesticide Manufacturing",CK3)),"","183") | KT3: =if(ISERROR(SEARCH("Pharmaceutical and Medicinal Product Manufacturing",CK3)),"","184") | KU3: =if(ISERROR(SEARCH("Other Basic Chemical Product Manufacturing",CK3)),"","189") | KV3: =if(ISERROR(SEARCH("Beverage Manufacturing",CR3)),"","121") | KW3: =if(ISERROR(SEARCH("Cigarette and Tobacco Product Manufacturing",CR3)),"","122") | KX3: =if(ISERROR(SEARCH("Iron and Steel Forging",CT3)),"","221") | KY3: =if(ISERROR(SEARCH("Metal Container Manufacturing",CT3)),"","223") | KZ3: =if(ISERROR(SEARCH("Sheet Metal Product Manufacturing (except Metal Structural and Container Products)",CT3)),"","224") | LA3: =if(ISERROR(SEARCH("Structural Metal Product Manufacturing",CT3)),"","222") | LB3: =if(ISERROR(SEARCH("Other Fabricated Metal Product Manufacturing",CT3)),"","229") | LC3: =if(ISERROR(SEARCH("Bakery Product Manufacturing",CX3)),"","117") | LD3: =if(ISERROR(SEARCH("Dairy Product Manufacturing",CX3)),"","113") | LE3: =if(ISERROR(SEARCH("Fruit and Vegetable Processing",CX3)),"","114") | LF3: =if(ISERROR(SEARCH("Grain Mill and Cereal Product Manufacturing",CX3)),"","116") | LG3: =if(ISERROR(SEARCH("Meat and Meat Product Manufacturing",CX3)),"","111") | LH3: =if(ISERROR(SEARCH("Oil and Fat Manufacturing",CX3)),"","115") | LI3: =if(ISERROR(SEARCH("Seafood Processing",CX3)),"","112") | LJ3: =if(ISERROR(SEARCH("Sugar and Confectionery Manufacturing",CX3)),"","118") | LK3: =if(ISERROR(SEARCH("Other Food Product Manufacturing",CX3)),"","119") | LL3: =if(ISERROR(SEARCH("Furniture Manufacturing",DE3)),"","251") | LM3: =if(ISERROR(SEARCH("Other Manufacturing",DE3)),"","259") | LN3: =if(ISERROR(SEARCH("Computer and Electronic Equipment Manufacturing",DH3)),"","242") | LO3: =if(ISERROR(SEARCH("Domestic Appliance Manufacturing",DH3)),"","244") | LP3: =if(ISERROR(SEARCH("Electrical Equipment Manufacturing",DH3)),"","243") | LQ3: =if(ISERROR(SEARCH("Professional and Scientific Equipment Manufacturing",DH3)),"","241") | LR3: =if(ISERROR(SEARCH("Pump, Compressor, Heating and Ventilation Equipment Manufacturing",DH3)),"","245") | LS3: =if(ISERROR(SEARCH("Specialised Machinery and Equipment Manufacturing",DH3)),"","246") | LT3: =if(ISERROR(SEARCH("Other Machinery and Equipment Manufacturing",DH3)),"","249") | LU3: =if(ISERROR(SEARCH("Cement, Lime, Plaster and Concrete Product Manufacturing",DP3)),"","203") | LV3: =if(ISERROR(SEARCH("Ceramic Product Manufacturing",DP3)),"","202") | LW3: =if(ISERROR(SEARCH("Glass and Glass Product Manufacturing",DP3)),"","201") | LX3: =if(ISERROR(SEARCH("Other Non-Metallic Mineral Product Manufacturing",DP3)),"","209") | LY3: =if(ISERROR(SEARCH("Petroleum Refining and Petroleum Fuel Manufacturing",DS3)),"","170") | LZ3: =if(ISERROR(SEARCH("Other Petroleum and Coal Product Manufacturing",DS3)),"","170") | MA3: =if(ISERROR(SEARCH("Natural Rubber Product Manufacturing",DT3)),"","192") | MB3: =if(ISERROR(SEARCH("Polymer Product Manufacturing",DT3)),"","191") | MC3: =if(ISERROR(SEARCH("Basic Ferrous Metal Manufacturing",DV3)),"","211") | MD3: =if(ISERROR(SEARCH("Basic Ferrous Metal Product Manufacturing",DV3)),"","212") | ME3: =if(ISERROR(SEARCH("Basic Non-Ferrous Metal Manufacturing",DV3)),"","213") | MF3: =if(ISERROR(SEARCH("Basic Non-Ferrous Metal Product Manufacturing",DV3)),"","214") | MG3: =if(ISERROR(SEARCH("Printing and Printing Support Services",EA3)),"","161") | MH3: =if(ISERROR(SEARCH("Reproduction of Recorded Media",EA3)),"","162") | MI3: =if(ISERROR(SEARCH("Converted Paper Product Manufacturing",EC3)),"","152") | MJ3: =if(ISERROR(SEARCH("Pulp, Paper and Paperboard Manufacturing",EC3)),"","151") | MK3: =if(ISERROR(SEARCH("Clothing and Footwear Manufacturing",EE3)),"","135") | ML3: =if(ISERROR(SEARCH("Knitted Product Manufacturing",EE3)),"","134") | MM3: =if(ISERROR(SEARCH("Leather Tanning, Fur Dressing and Leather Product Manufacturing",EE3)),"","132") | MN3: =if(ISERROR(SEARCH("Textile Manufacturing",EE3)),"","131") | MO3: =if(ISERROR(SEARCH("Textile Product Manufacturing",EE3)),"","133") | MP3: =if(ISERROR(SEARCH("Motor Vehicle and Motor Vehicle Part Manufacturing",EI3)),"","231") | MQ3: =if(ISERROR(SEARCH("Other Transport Equipment Manufacturing",EI3)),"","239") | MR3: =if(ISERROR(SEARCH("Log Sawmilling and Timber Dressing",EL3)),"","141") | MS3: =if(ISERROR(SEARCH("Other Wood Product Manufacturing",EL3)),"","149") | MT3: =if(ISERROR(SEARCH("Coal Mining",EO3)),"","060") | MU3: =if(ISERROR(SEARCH("Exploration",EP3)),"","101") | MV3: =if(ISERROR(SEARCH("Other Mining Support Services",EP3)),"","109") | MW3: =if(ISERROR(SEARCH("Metal Ore Mining",EO3)),"","080") | MX3: =if(ISERROR(SEARCH("Construction Material Mining",ES3)),"","091") | MY3: =if(ISERROR(SEARCH("Oil and Gas Extraction",EO3)),"","070") | MZ3: =if(ISERROR(SEARCH("Other Non-Metallic Mineral Mining and Quarrying",ES3)),"","099") | NA3: =if(ISERROR(SEARCH("Computer System Design and Related Services",EU3)),"","700") | NB3: =if(ISERROR(SEARCH("Advertising Services",EV3)),"","694") | NC3: =if(ISERROR(SEARCH("Architectural, Engineering and Technical Services",EV3)),"","692") | ND3: =if(ISERROR(SEARCH("Legal and Accounting Services",EV3)),"","693") | NE3: =if(ISERROR(SEARCH("Management and Related Consulting Services",EV3)),"","696") | NF3: =if(ISERROR(SEARCH("Market Research and Statistical Services",EV3)),"","695") | NG3: =if(ISERROR(SEARCH("Scientific Research Services",EV3)),"","691") | NH3: =if(ISERROR(SEARCH("Veterinary Services",EV3)),"","697") | NI3: =if(ISERROR(SEARCH("Other Professional, Scientific and Technical Services",EV3)),"","699") | NJ3: =if(ISERROR(SEARCH("Central Government Administration",FB3)),"","751") | NK3: =if(ISERROR(SEARCH("State Government Administration",FB3)),"","752") | NL3: =if(ISERROR(SEARCH("Local Government Administration",FB3)),"","753") | NM3: =if(ISERROR(SEARCH("Justice",FB3)),"","754") | NN3: =if(ISERROR(SEARCH("Government Representation",FB3)),"","755") | NO3: =if(ISERROR(SEARCH("Defence",FA3)),"","760") | NP3: =if(ISERROR(SEARCH("Public Order and Safety Services",FD3)),"","771") | NQ3: =if(ISERROR(SEARCH("Regulatory Services",FD3)),"","772") | NR3: =if(ISERROR(SEARCH("Property Operators",FG3)),"","671") | NS3: =if(ISERROR(SEARCH("Real Estate Services",FG3)),"","672") | NT3: =if(ISERROR(SEARCH("Farm Animal and Bloodstock Leasing",FI3)),"","662") | NU3: =if(ISERROR(SEARCH("Motor Vehicle and Transport Equipment Rental and Hiring",FI3)),"","661") | NV3: =if(ISERROR(SEARCH("Non-Financial Intangible Assets (Except Copyrights) Leasing",FI3)),"","664") | NW3: =if(ISERROR(SEARCH("Other Goods and Equipment Rental and Hiring",FI3)),"","663") | NX3: =if(ISERROR(SEARCH("Supermarket and Grocery Stores",FM3)),"","411") | NY3: =if(ISERROR(SEARCH("Specialised Food Retailing",FM3)),"","412") | NZ3: =if(ISERROR(SEARCH("Fuel Retailing",FL3)),"","400") | OA3: =if(ISERROR(SEARCH("Motor Vehicle Parts and Tyre Retailing",FO3)),"","392") | OB3: =if(ISERROR(SEARCH("Motor Vehicle Retailing",FO3)),"","391") | OC3: =if(ISERROR(SEARCH("Non-Store Retailing",FR3)),"","431") | OD3: =if(ISERROR(SEARCH("Retail Commission-Based Buying and/or Selling",FR3)),"","432") | OE3: =if(ISERROR(SEARCH("Clothing, Footwear and Personal Accessory Retailing",FS3)),"","425") | OF3: =if(ISERROR(SEARCH("Department Stores",FS3)),"","426") | OG3: =if(ISERROR(SEARCH("Electrical and Electronic Goods Retailing",FS3)),"","422") | OH3: =if(ISERROR(SEARCH("Furniture, Floor Coverings, Houseware and Textile Goods Retailing",FS3)),"","421") | OI3: =if(ISERROR(SEARCH("Hardware, Building and Garden Supplies Retailing",FS3)),"","423") | OJ3: =if(ISERROR(SEARCH("Pharmaceutical and Other Store-Based Retailing",FS3)),"","427") | OK3: =if(ISERROR(SEARCH("Recreational Goods Retailing",FS3)),"","424") | OL3: =if(ISERROR(SEARCH("Air and Space Transport",FZ3)),"","490") | OM3: =if(ISERROR(SEARCH("Postal and Courier Pick-up and Delivery Services",FZ3)),"","510") | ON3: =if(ISERROR(SEARCH("Rail Freight Transport",GB3)),"","471") | OO3: =if(ISERROR(SEARCH("Rail Passenger Transport",GB3)),"","472") | OP3: =if(ISERROR(SEARCH("Road Freight Transport",GC3)),"","461") | OQ3: =if(ISERROR(SEARCH("Road Passenger Transport",GC3)),"","462") | OR3: =if(ISERROR(SEARCH("Airport Operations and Other Air Transport Support Services",GE3)),"","522") | OS3: =if(ISERROR(SEARCH("Water Transport Support Services",GE3)),"","521") | OT3: =if(ISERROR(SEARCH("Other Transport Support Services",GE3)),"","529") | OU3: =if(ISERROR(SEARCH("Warehousing and Storage Services",FZ3)),"","530") | OV3: =if(ISERROR(SEARCH("Water Freight Transport",GI3)),"","481") | OW3: =if(ISERROR(SEARCH("Water Freight Transport",GI3)),"","482") | OX3: =if(ISERROR(SEARCH("Pipeline and Other Transport",GJ3)),"","502") | OY3: =if(ISERROR(SEARCH("Scenic and Sightseeing Transport",GJ3)),"","501") | OZ3: =if(ISERROR(SEARCH("Agricultural Product Wholesaling",GM3)),"","331") | PA3: =if(ISERROR(SEARCH("Mineral, Metal and Chemical Wholesaling",GM3)),"","332") | PB3: =if(ISERROR(SEARCH("Timber and Hardware Goods Wholesaling",GM3)),"","333") | PC3: =if(ISERROR(SEARCH("Commission-Based Wholesaling",GL3)),"","380") | PD3: =if(ISERROR(SEARCH("Grocery, Liquor and Tobacco Product Wholesaling",GL3)),"","360") | PE3: =if(ISERROR(SEARCH("Specialised Industrial Machinery and Equipment Wholesaling",GR3)),"","341") | PF3: =if(ISERROR(SEARCH("Other Machinery and Equipment Wholesaling",GR3)),"","349") | PG3: =if(ISERROR(SEARCH("Motor Vehicle and Motor Vehicle Parts Wholesaling",GL3)),"","350") | PH3: =if(ISERROR(SEARCH("Textile, Clothing and Footwear Wholesaling",GV3)),"","371") | PI3: =if(ISERROR(SEARCH("Furniture, Floor Covering and Other Goods Wholesaling",GV3)),"","373") | PJ3: =if(ISERROR(SEARCH("Pharmaceutical and Toiletry Goods Wholesaling",GV3)),"","372") | PK3: =if(ISERROR(SEARCH("Civic, Professional and Other Interest Group Services",GZ3)),"","955") | PL3: =if(ISERROR(SEARCH("Funeral, Crematorium and Cemetery Services",GZ3)),"","952") | PM3: =if(ISERROR(SEARCH("Personal Care Services",GZ3)),"","951") | PN3: =if(ISERROR(SEARCH("Religious Services",GZ3)),"","954") | PO3: =if(ISERROR(SEARCH("Other Personal Services",GZ3)),"","953") | PP3: =if(ISERROR(SEARCH("Private Households Employing Staff and Undifferentiated Goods- and Service-Producing Activities of Households for Own Use",GY3)),"","960") | PQ3: =if(ISERROR(SEARCH("Automotive Repair and Maintenance",HE3)),"","941") | PR3: =if(ISERROR(SEARCH("Machinery and Equipment Repair and Maintenance",HE3)),"","942") | PS3: =if(ISERROR(SEARCH("Other Repair and Maintenance",HE3)),"","949")
